{"trial_id": "01", "hyperparameters": {"space": [{"class_name": "Int", "config": {"name": "filters", "default": null, "conditions": [], "min_value": 32, "max_value": 512, "step": 32, "sampling": "linear"}}, {"class_name": "Choice", "config": {"name": "kernel_size", "default": 3, "conditions": [], "values": [3, 5, 7], "ordered": true}}, {"class_name": "Int", "config": {"name": "dense_units", "default": null, "conditions": [], "min_value": 32, "max_value": 512, "step": 32, "sampling": "linear"}}, {"class_name": "Float", "config": {"name": "learning_rate", "default": 0.0001, "conditions": [], "min_value": 0.0001, "max_value": 0.01, "step": null, "sampling": "log"}}], "values": {"filters": 128, "kernel_size": 3, "dense_units": 448, "learning_rate": 0.00013003682355510184}}, "metrics": {"metrics": {}}, "score": null, "best_step": 0, "status": "FAILED", "message": "Traceback (most recent call last):\n  File \"C:\\Users\\firoj\\anaconda3\\Lib\\site-packages\\keras_tuner\\src\\engine\\base_tuner.py\", line 273, in _try_run_and_update_trial\n    self._run_and_update_trial(trial, *fit_args, **fit_kwargs)\n  File \"C:\\Users\\firoj\\anaconda3\\Lib\\site-packages\\keras_tuner\\src\\engine\\base_tuner.py\", line 238, in _run_and_update_trial\n    results = self.run_trial(trial, *fit_args, **fit_kwargs)\n              ^^^^^^^^^^^^^^^^^^^^^^^^^^^^^^^^^^^^^^^^^^^^^^\n  File \"C:\\Users\\firoj\\anaconda3\\Lib\\site-packages\\keras_tuner\\src\\engine\\tuner.py\", line 314, in run_trial\n    obj_value = self._build_and_fit_model(trial, *args, **copied_kwargs)\n                ^^^^^^^^^^^^^^^^^^^^^^^^^^^^^^^^^^^^^^^^^^^^^^^^^^^^^^^^\n  File \"C:\\Users\\firoj\\anaconda3\\Lib\\site-packages\\keras_tuner\\src\\engine\\tuner.py\", line 233, in _build_and_fit_model\n    results = self.hypermodel.fit(hp, model, *args, **kwargs)\n              ^^^^^^^^^^^^^^^^^^^^^^^^^^^^^^^^^^^^^^^^^^^^^^^\n  File \"C:\\Users\\firoj\\anaconda3\\Lib\\site-packages\\keras_tuner\\src\\engine\\hypermodel.py\", line 149, in fit\n    return model.fit(*args, **kwargs)\n           ^^^^^^^^^^^^^^^^^^^^^^^^^^\n  File \"C:\\Users\\firoj\\anaconda3\\Lib\\site-packages\\keras\\src\\utils\\traceback_utils.py\", line 70, in error_handler\n    raise e.with_traceback(filtered_tb) from None\n  File \"C:\\Users\\firoj\\AppData\\Local\\Temp\\__autograph_generated_file_78e097x.py\", line 18, in tf__train_function\n    raise\nValueError: in user code:\n\n    File \"C:\\Users\\firoj\\anaconda3\\Lib\\site-packages\\keras\\src\\engine\\training.py\", line 1377, in train_function  *\n        return step_function(self, iterator)\n    File \"C:\\Users\\firoj\\anaconda3\\Lib\\site-packages\\keras\\src\\engine\\training.py\", line 1360, in step_function  **\n        outputs = model.distribute_strategy.run(run_step, args=(data,))\n    File \"C:\\Users\\firoj\\anaconda3\\Lib\\site-packages\\keras\\src\\engine\\training.py\", line 1349, in run_step  **\n        outputs = model.train_step(data)\n    File \"C:\\Users\\firoj\\anaconda3\\Lib\\site-packages\\keras\\src\\engine\\training.py\", line 1126, in train_step\n        y_pred = self(x, training=True)\n    File \"C:\\Users\\firoj\\anaconda3\\Lib\\site-packages\\keras\\src\\utils\\traceback_utils.py\", line 70, in error_handler\n        raise e.with_traceback(filtered_tb) from None\n    File \"C:\\Users\\firoj\\anaconda3\\Lib\\site-packages\\keras\\src\\engine\\input_spec.py\", line 298, in assert_input_compatibility\n        raise ValueError(\n\n    ValueError: Input 0 of layer \"sequential\" is incompatible with the layer: expected shape=(None, 100, 10), found shape=(None, 1, 10)\n\n"}